Workbook

Sheet Cover
B2: Electrical Design Calculations: G+2 Commercial Office Building
B3: Prepared by Anuj Kumar (B.Tech EE, DTU). Portfolio design exercise
B5: Sheet | C5: What it contains
B6: Inputs | C6: Design inputs and assumptions: supply, margins, loading limits, derating, soil data. Change these and every sheet updates.
B7: Lighting | C7: Lumen-method lighting design per space (room index, UF, MF, fixture count, achieved lux, LPD vs ECBC 2017).
B8: Load_Schedule | C8: Connected load, demand factors, maximum demand (kW/kVAr/kVA), essential (DG) and UPS-backed loads, feeder tagging.
B9: Sizing | C9: Transformer, DG, UPS + battery and APFC sizing; LV full-load current and fault level.
B10: Cable_Schedule | C10: Feeder cables from the Main LT Panel: breaker rating, derating, size by ampacity and by voltage drop, final selection.
B11: Earthing | C11: Earth electrode resistance (IS 3043), number of electrodes, strip interconnection, earth conductor sizing.
B12: Ref_Tables | C12: Cable data, utilisation factors, standard equipment ratings, IS 3043 parallel-electrode factors.
B14: Colour legend
B15: Blue text, yellow fill | C15: Input: edit these
B16: Black text | C16: Formula: do not overwrite
B17: Green text | C17: Link from another sheet
B18: Green fill | C18: Key result / selected equipment
B20: Building basis
C21: Ground + 2 floors, 600 m² per floor (30 m x 20 m), commercial office, Delhi.
C22: GF: reception/lobby, cafeteria, open office, electrical room. FF & SF: open office, cabins, meeting room.
C23: Supply: 11 kV HT from DISCOM → 11/0.433 kV Dyn11 oil-type transformer → Main LT Panel (MLTP). DG backup via AMF panel; UPS for IT loads; APFC at MLTP.
C24: Earthing system: TN-S at LV.
B26: Codes & standards referred
C27: IS 732:2019 (wiring installations); IS 3043:2018 (earthing); IS 3646 / NBC 2016 Part 8 Sec 2 (lighting & electrical); ECBC 2017 (lighting power density)
C28: IS 1180 (distribution transformers); IEC 60502-1 / IS 7098 (XLPE cables); IEC 60364-5-52 (cable selection, voltage drop); CEA (Measures relating to Safety & Electric Supply) Regulations 2023
B30: Limitations
C31: Cable data from the Havells International Cables catalogue (IEC 60502-1). Reactance is a typical value since the catalogue does not list it.
C32: Demand factors are typical consultant practice. Confirm them against the client brief and DISCOM requirements.
C33: Short-circuit withstand of cables and the DG transient response (ISO 8528-5) still need checking with manufacturer data.

Sheet Inputs
B2: Design inputs
B3: Parameter | C3: Value | D3: Unit | E3: Basis / note
B4: Area per floor | C4: 600 | D4: m² | E4: 30 m x 20 m
B5: Number of floors | C5: 3 | D5: nos | E5: G + 2
B6: HT supply voltage | C6: 11 | D6: kV | E6: DISCOM 11 kV supply (load above LT limit, so confirm with DISCOM)
B7: LT system voltage (L-L) | C7: 415 | D7: V | E7: 3-ph, 4-wire, 50 Hz
B8: Overall diversity factor | C8: 0.9 | D8: - | E8: Applied over the sum of feeder demands
B9: Future expansion margin | C9: 0.2 | D9: - | E9: 20%: typical consultant allowance
B10: Transformer max loading | C10: 0.8 | D10: - | E10: Sized for ≤80% loading at full demand + margin
B11: Transformer impedance | C11: 0.045 | D11: p.u. | E11: IS 1180 typical for 250–630 kVA
B12: DG max loading | C12: 0.8 | D12: - | E12: Prime-rated DG at ≤80%
B13: Target power factor | C13: 0.98 | D13: - | E13: DISCOM incentive range
B14: UPS output PF | C14: 0.9 | D14: - | E14: Online double-conversion UPS
B15: UPS efficiency | C15: 0.93 | D15: -
B16: UPS battery backup time | C16: 0.5 | D16: h | E16: 30 min
B17: Battery DC bus voltage | C17: 384 | D17: V | E17: 32 x 12 V VRLA blocks
B18: Battery ageing / design factor | C18: 1.25 | D18: - | E18: IEEE 485 ageing factor
B19: UPS battery charging allowance | C19: 0.1 | D19: - | E19: Added to UPS input demand
B20: Feeder voltage-drop limit | C20: 0.03 | D20: - | E20: 3% on main feeders; ≤5% end-to-end (IS 732 / IEC 60364-5-52)
B21: Temperature derating factor | C21: 0.87 | D21: - | E21: Havells rating factor for 45°C air (catalogue base 30°C)
B22: Grouping derating factor | C22: 0.71 | D22: - | E22: Havells: multicore touching, 2 racks x 4 cables
B23: Soil resistivity ρ | C23: 50 | D23: Ω·m | E23: Assumed for Delhi alluvium; lies within the 10–130 Ω·m range reported for West Delhi (2014 resistivity survey). Replace with site Wenner 4-point test (IS 3043)
B24: Earth electrode length L | C24: 3 | D24: m | E24: GI pipe electrode
B25: Effective electrode diameter d | C25: 0.1 | D25: m | E25: 40 mm pipe in 100 mm bore with backfill compound
B26: Electrode spacing s | C26: 6 | D26: m | E26: ≥ 2L
B27: Target earth grid resistance | C27: 1 | D27: Ω | E27: Typical requirement for substation earth grid
... B29: Strip width w | C29: 0.05 | D29: m | E29: 50 mm
B30: Strip burial depth t | C30: 0.5 | D30: m
B31: Earth fault clearing time | C31: 1 | D31: s | E31: Conservative (IS 3043)
B32: k factor, GI steel | C32: 80 | D32: - | E32: IS 3043, bare steel
B33: Corrosion allowance on earth conductor | C33: 1.5 | D33: - | E33: Multiplier on minimum area

Sheet Lighting
A1: Lighting design: lumen method N = (E x A) / (Φ x UF x MF)
A2: Hm = luminaire to working plane (3.0 m false ceiling − 0.75 m desk = 2.25 m). Room index K = A / (Hm x (L + W)). UF from Ref_Tables.
A4: Floor | B4: Space | C4: Length (m) | D4: Width (m) | E4: Area (m²) | F4: Hm (m) | G4: Room index K | H4: UF | I4: MF | J4: Target lux (E) | K4: Luminaire | L4: Lumens / fixture | M4: W / fixture | N4: Fixtures (N) | O4: Achieved lux | P4: Installed W | Q4: LPD (W/m²) | R4: ECBC limit (W/m²) | S4: Check
A5: GF | B5: Reception / lobby | C5: 10 | D5: 10 | E5: =C5*D5 -> 100 | F5: 2.25 | G5: =E5/(F5*(C5+D5)) -> 2.2222222 | H5: =IFERROR(INDEX(Ref_Tables!$I$5:$I$14,MATCH(G5,Ref_Tables!$H$5:$H$14,1)),Ref_Tables!$I$5) -> 0.72 | I5: 0.8 | J5: 150 | K5: LED downlight 18 W | L5: 1800 | M5: 18 | N5: =ROUNDUP(J5*E5/(L5*H5*I5),0) -> 15 | O5: =N5*L5*H5*I5/E5 -> 155.52 | P5: =N5*M5 -> 270 | Q5: =P5/E5 -> 2.7 | R5: 9.5 | S5: =IF(AND(O5>=J5,Q5<=R5),"OK","CHECK") -> OK
A6: GF | B6: Cafeteria | C6: 15 | D6: 10 | E6: =C6*D6 -> 150 | F6: 2.25 | G6: =E6/(F6*(C6+D6)) -> 2.6666667 | H6: =IFERROR(INDEX(Ref_Tables!$I$5:$I$14,MATCH(G6,Ref_Tables!$H$5:$H$14,1)),Ref_Tables!$I$5) -> 0.75 | I6: 0.8 | J6: 200 | K6: LED downlight 18 W | L6: 1800 | M6: 18 | N6: =ROUNDUP(J6*E6/(L6*H6*I6),0) -> 28 | O6: =N6*L6*H6*I6/E6 -> 201.6 | P6: =N6*M6 -> 504 | Q6: =P6/E6 -> 3.36 | R6: 9.5 | S6: =IF(AND(O6>=J6,Q6<=R6),"OK","CHECK") -> OK
A7: GF | B7: Open office | C7: 20 | D7: 15 | E7: =C7*D7 -> 300 | F7: 2.25 | G7: =E7/(F7*(C7+D7)) -> 3.8095238 | H7: =IFERROR(INDEX(Ref_Tables!$I$5:$I$14,MATCH(G7,Ref_Tables!$H$5:$H$14,1)),Ref_Tables!$I$5) -> 0.78 | I7: 0.8 | J7: 300 | K7: LED panel 600x600 36 W | L7: 3600 | M7: 36 | N7: =ROUNDUP(J7*E7/(L7*H7*I7),0) -> 41 | O7: =N7*L7*H7*I7/E7 -> 307.008 | P7: =N7*M7 -> 1476 | Q7: =P7/E7 -> 4.92 | R7: 9.5 | S7: =IF(AND(O7>=J7,Q7<=R7),"OK","CHECK") -> OK
A8: GF | B8: Electrical room | C8: 10 | D8: 5 | E8: =C8*D8 -> 50 | F8: 2.25 | G8: =E8/(F8*(C8+D8)) -> 1.4814815 | H8: =IFERROR(INDEX(Ref_Tables!$I$5:$I$14,MATCH(G8,Ref_Tables!$H$5:$H$14,1)),Ref_Tables!$I$5) -> 0.63 | I8: 0.8 | J8: 150 | K8: LED batten 20 W | L8: 2000 | M8: 20 | N8: =ROUNDUP(J8*E8/(L8*H8*I8),0) -> 8 | O8: =N8*L8*H8*I8/E8 -> 161.28 | P8: =N8*M8 -> 160 | Q8: =P8/E8 -> 3.2 | R8: 9.5 | S8: =IF(AND(O8>=J8,Q8<=R8),"OK","CHECK") -> OK
A9: FF | B9: Open office | C9: 25 | D9: 18 | E9: =C9*D9 -> 450 | F9: 2.25 | G9: =E9/(F9*(C9+D9)) -> 4.6511628 | H9: =IFERROR(INDEX(Ref_Tables!$I$5:$I$14,MATCH(G9,Ref_Tables!$H$5:$H$14,1)),Ref_Tables!$I$5) -> 0.81 | I9: 0.8 | J9: 300 | K9: LED panel 600x600 36 W | L9: 3600 | M9: 36 | N9: =ROUNDUP(J9*E9/(L9*H9*I9),0) -> 58 | O9: =N9*L9*H9*I9/E9 -> 300.672 | P9: =N9*M9 -> 2088 | Q9: =P9/E9 -> 4.64 | R9: 9.5 | S9: =IF(AND(O9>=J9,Q9<=R9),"OK","CHECK") -> OK
A10: FF | B10: Cabins | C10: 10 | D10: 8 | E10: =C10*D10 -> 80 | F10: 2.25 | G10: =E10/(F10*(C10+D10)) -> 1.9753086 | H10: =IFERROR(INDEX(Ref_Tables!$I$5:$I$14,MATCH(G10,Ref_Tables!$H$5:$H$14,1)),Ref_Tables!$I$5) -> 0.67 | I10: 0.8 | J10: 300 | K10: LED panel 600x600 36 W | L10: 3600 | M10: 36 | N10: =ROUNDUP(J10*E10/(L10*H10*I10),0) -> 13 | O10: =N10*L10*H10*I10/E10 -> 313.56 | P10: =N10*M10 -> 468 | Q10: =P10/E10 -> 5.85 | R10: 9.5 | S10: =IF(AND(O10>=J10,Q10<=R10),"OK","CHECK") -> OK
A11: FF | B11: Meeting room | C11: 10 | D11: 7 | E11: =C11*D11 -> 70 | F11: 2.25 | G11: =E11/(F11*(C11+D11)) -> 1.8300654 | H11: =IFERROR(INDEX(Ref_Tables!$I$5:$I$14,MATCH(G11,Ref_Tables!$H$5:$H$14,1)),Ref_Tables!$I$5) -> 0.67 | I11: 0.8 | J11: 300 | K11: LED panel 600x600 36 W | L11: 3600 | M11: 36 | N11: =ROUNDUP(J11*E11/(L11*H11*I11),0) -> 11 | O11: =N11*L11*H11*I11/E11 -> 303.22286 | P11: =N11*M11 -> 396 | Q11: =P11/E11 -> 5.6571429 | R11: 9.5 | S11: =IF(AND(O11>=J11,Q11<=R11),"OK","CHECK") -> OK
A12: SF | B12: Open office | C12: 25 | D12: 18 | E12: =C12*D12 -> 450 | F12: 2.25 | G12: =E12/(F12*(C12+D12)) -> 4.6511628 | H12: =IFERROR(INDEX(Ref_Tables!$I$5:$I$14,MATCH(G12,Ref_Tables!$H$5:$H$14,1)),Ref_Tables!$I$5) -> 0.81 | I12: 0.8 | J12: 300 | K12: LED panel 600x600 36 W | L12: 3600 | M12: 36 | N12: =ROUNDUP(J12*E12/(L12*H12*I12),0) -> 58 | O12: =N12*L12*H12*I12/E12 -> 300.672 | P12: =N12*M12 -> 2088 | Q12: =P12/E12 -> 4.64 | R12: 9.5 | S12: =IF(AND(O12>=J12,Q12<=R12),"OK","CHECK") -> OK
A13: SF | B13: Cabins | C13: 10 | D13: 8 | E13: =C13*D13 -> 80 | F13: 2.25 | G13: =E13/(F13*(C13+D13)) -> 1.9753086 | H13: =IFERROR(INDEX(Ref_Tables!$I$5:$I$14,MATCH(G13,Ref_Tables!$H$5:$H$14,1)),Ref_Tables!$I$5) -> 0.67 | I13: 0.8 | J13: 300 | K13: LED panel 600x600 36 W | L13: 3600 | M13: 36 | N13: =ROUNDUP(J13*E13/(L13*H13*I13),0) -> 13 | O13: =N13*L13*H13*I13/E13 -> 313.56 | P13: =N13*M13 -> 468 | Q13: =P13/E13 -> 5.85 | R13: 9.5 | S13: =IF(AND(O13>=J13,Q13<=R13),"OK","CHECK") -> OK
A14: SF | B14: Meeting room | C14: 10 | D14: 7 | E14: =C14*D14 -> 70 | F14: 2.25 | G14: =E14/(F14*(C14+D14)) -> 1.8300654 | H14: =IFERROR(INDEX(Ref_Tables!$I$5:$I$14,MATCH(G14,Ref_Tables!$H$5:$H$14,1)),Ref_Tables!$I$5) -> 0.67 | I14: 0.8 | J14: 300 | K14: LED panel 600x600 36 W | L14: 3600 | M14: 36 | N14: =ROUNDUP(J14*E14/(L14*H14*I14),0) -> 11 | O14: =N14*L14*H14*I14/E14 -> 303.22286 | P14: =N14*M14 -> 396 | Q14: =P14/E14 -> 5.6571429 | R14: 9.5 | S14: =IF(AND(O14>=J14,Q14<=R14),"OK","CHECK") -> OK
B15: Total | E15: =SUM(E5:E14) -> 1800 | N15: =SUM(N5:N14) -> 256 | P15: =SUM(P5:P14) -> 8314 | Q15: =P15/E15 -> 4.6188889
A17: Lux targets per NBC 2016 Part 8 / IS 3646 (office 300, cafeteria 200, lobby & plant room 150). MF 0.8 for LED in clean office. ECBC 2017 building-area LPD (office) 9.5 W/m². Corridors and toilets not included.

Sheet Load_Schedule
A1: Load schedule & maximum demand
A2: MD = Connected load x Demand factor. kVAr = kW x tan(cos⁻¹ PF). DG demand uses its own factor (load shedding on DG). Feeder tag links each load to its MLTP outgoing feeder (Cable_Schedule).
A4: S.No | B4: Floor / area | C4: Load | D4: Feeder | E4: Qty | F4: kW / unit | G4: Connected load (kW) | H4: PF | I4: Demand factor | J4: MD (kW) | K4: MD (kVAr) | L4: MD (kVA) | M4: Essential (DG) | N4: DG factor | O4: DG demand (kW) | P4: DG demand (kVAr) | Q4: UPS backed | R4: Notes
A5: 1 | B5: GF | C5: Lighting (LED) | D5: F01 | E5: 1 | F5: =SUMIFS(Lighting!$P$5:$P$14,Lighting!$A$5:$A$14,"GF")/1000 -> 2.41 | G5: =E5*F5 -> 2.41 | H5: 0.9 | I5: 0.9 | J5: =G5*I5 -> 2.169 | K5: =J5*TAN(ACOS(H5)) -> 1.0504946 | L5: =SQRT(J5^2+K5^2) -> 2.41 | M5: Y | N5: 0.9 | O5: =IF(M5="Y",G5*N5,0) -> 2.169 | P5: =O5*TAN(ACOS(H5)) -> 1.0504946 | Q5: N | R5: From Lighting sheet
A6: 2 | B6: GF | C6: 6A raw power sockets | D6: F01 | E6: 40 | F6: 0.1 | G6: =E6*F6 -> 4 | H6: 0.8 | I6: 0.3 | J6: =G6*I6 -> 1.2 | K6: =J6*TAN(ACOS(H6)) -> 0.9 | L6: =SQRT(J6^2+K6^2) -> 1.5 | M6: Y | N6: 0.3 | O6: =IF(M6="Y",G6*N6,0) -> 1.2 | P6: =O6*TAN(ACOS(H6)) -> 0.9 | Q6: N
A7: 3 | B7: GF | C7: 16A power sockets | D7: F01 | E7: 8 | F7: 1 | G7: =E7*F7 -> 8 | H7: 0.8 | I7: 0.4 | J7: =G7*I7 -> 3.2 | K7: =J7*TAN(ACOS(H7)) -> 2.4 | L7: =SQRT(J7^2+K7^2) -> 4 | M7: Y | N7: 0.4 | O7: =IF(M7="Y",G7*N7,0) -> 3.2 | P7: =O7*TAN(ACOS(H7)) -> 2.4 | Q7: N
A8: 4 | B8: GF | C8: Cafeteria / pantry equipment | D8: F01 | E8: 1 | F8: 15 | G8: =E8*F8 -> 15 | H8: 0.9 | I8: 0.6 | J8: =G8*I8 -> 9 | K8: =J8*TAN(ACOS(H8)) -> 4.3588989 | L8: =SQRT(J8^2+K8^2) -> 10 | M8: Y | N8: 0.6 | O8: =IF(M8="Y",G8*N8,0) -> 9 | P8: =O8*TAN(ACOS(H8)) -> 4.3588989 | Q8: N
A9: 5 | B9: GF | C9: Toilet exhaust fans | D9: F01 | E9: 4 | F9: 0.1 | G9: =E9*F9 -> 0.4 | H9: 0.8 | I9: 1 | J9: =G9*I9 -> 0.4 | K9: =J9*TAN(ACOS(H9)) -> 0.3 | L9: =SQRT(J9^2+K9^2) -> 0.5 | M9: Y | N9: 1 | O9: =IF(M9="Y",G9*N9,0) -> 0.4 | P9: =O9*TAN(ACOS(H9)) -> 0.3 | Q9: N
A10: 6 | B10: GF | C10: Server room split AC | D10: F01 | E10: 1 | F10: 2.5 | G10: =E10*F10 -> 2.5 | H10: 0.85 | I10: 1 | J10: =G10*I10 -> 2.5 | K10: =J10*TAN(ACOS(H10)) -> 1.5493608 | L10: =SQRT(J10^2+K10^2) -> 2.9411765 | M10: Y | N10: 1 | O10: =IF(M10="Y",G10*N10,0) -> 2.5 | P10: =O10*TAN(ACOS(H10)) -> 1.5493608 | Q10: N
A11: 7 | B11: GF | C11: Workstation UPS sockets | D11: F08 | E11: 25 | F11: 0.15 | G11: =E11*F11 -> 3.75 | H11: 0.9 | I11: 0.8 | J11: =G11*I11 -> 3 | K11: =J11*TAN(ACOS(H11)) -> 1.4529663 | L11: =SQRT(J11^2+K11^2) -> 3.3333333 | M11: Y | N11: 0.8 | O11: =IF(M11="Y",G11*N11,0) -> 3 | P11: =O11*TAN(ACOS(H11)) -> 1.4529663 | Q11: Y | R11: Fed via UPS
A12: 8 | B12: GF | C12: Server / IT rack | D12: F08 | E12: 1 | F12: 5 | G12: =E12*F12 -> 5 | H12: 0.9 | I12: 1 | J12: =G12*I12 -> 5 | K12: =J12*TAN(ACOS(H12)) -> 2.4216105 | L12: =SQRT(J12^2+K12^2) -> 5.5555556 | M12: Y | N12: 1 | O12: =IF(M12="Y",G12*N12,0) -> 5 | P12: =O12*TAN(ACOS(H12)) -> 2.4216105 | Q12: Y | R12: Fed via UPS
A13: 9 | B13: FF | C13: Lighting (LED) | D13: F02 | E13: 1 | F13: =SUMIFS(Lighting!$P$5:$P$14,Lighting!$A$5:$A$14,"FF")/1000 -> 2.952 | G13: =E13*F13 -> 2.952 | H13: 0.9 | I13: 0.9 | J13: =G13*I13 -> 2.6568 | K13: =J13*TAN(ACOS(H13)) -> 1.286747 | L13: =SQRT(J13^2+K13^2) -> 2.952 | M13: Y | N13: 0.9 | O13: =IF(M13="Y",G13*N13,0) -> 2.6568 | P13: =O13*TAN(ACOS(H13)) -> 1.286747 | Q13: N | R13: From Lighting sheet
A14: 10 | B14: FF | C14: 6A raw power sockets | D14: F02 | E14: 60 | F14: 0.1 | G14: =E14*F14 -> 6 | H14: 0.8 | I14: 0.3 | J14: =G14*I14 -> 1.8 | K14: =J14*TAN(ACOS(H14)) -> 1.35 | L14: =SQRT(J14^2+K14^2) -> 2.25 | M14: Y | N14: 0.3 | O14: =IF(M14="Y",G14*N14,0) -> 1.8 | P14: =O14*TAN(ACOS(H14)) -> 1.35 | Q14: N
A15: 11 | B15: FF | C15: 16A power sockets | D15: F02 | E15: 10 | F15: 1 | G15: =E15*F15 -> 10 | H15: 0.8 | I15: 0.4 | J15: =G15*I15 -> 4 | K15: =J15*TAN(ACOS(H15)) -> 3 | L15: =SQRT(J15^2+K15^2) -> 5 | M15: Y | N15: 0.4 | O15: =IF(M15="Y",G15*N15,0) -> 4 | P15: =O15*TAN(ACOS(H15)) -> 3 | Q15: N
A16: 12 | B16: FF | C16: Toilet exhaust fans | D16: F02 | E16: 4 | F16: 0.1 | G16: =E16*F16 -> 0.4 | H16: 0.8 | I16: 1 | J16: =G16*I16 -> 0.4 | K16: =J16*TAN(ACOS(H16)) -> 0.3 | L16: =SQRT(J16^2+K16^2) -> 0.5 | M16: Y | N16: 1 | O16: =IF(M16="Y",G16*N16,0) -> 0.4 | P16: =O16*TAN(ACOS(H16)) -> 0.3 | Q16: N
A17: 13 | B17: FF | C17: Workstation UPS sockets | D17: F08 | E17: 60 | F17: 0.15 | G17: =E17*F17 -> 9 | H17: 0.9 | I17: 0.8 | J17: =G17*I17 -> 7.2 | K17: =J17*TAN(ACOS(H17)) -> 3.4871192 | L17: =SQRT(J17^2+K17^2) -> 8 | M17: Y | N17: 0.8 | O17: =IF(M17="Y",G17*N17,0) -> 7.2 | P17: =O17*TAN(ACOS(H17)) -> 3.4871192 | Q17: Y | R17: Fed via UPS
A18: 14 | B18: SF | C18: Lighting (LED) | D18: F03 | E18: 1 | F18: =SUMIFS(Lighting!$P$5:$P$14,Lighting!$A$5:$A$14,"SF")/1000 -> 2.952 | G18: =E18*F18 -> 2.952 | H18: 0.9 | I18: 0.9 | J18: =G18*I18 -> 2.6568 | K18: =J18*TAN(ACOS(H18)) -> 1.286747 | L18: =SQRT(J18^2+K18^2) -> 2.952 | M18: Y | N18: 0.9 | O18: =IF(M18="Y",G18*N18,0) -> 2.6568 | P18: =O18*TAN(ACOS(H18)) -> 1.286747 | Q18: N | R18: From Lighting sheet
A19: 15 | B19: SF | C19: 6A raw power sockets | D19: F03 | E19: 60 | F19: 0.1 | G19: =E19*F19 -> 6 | H19: 0.8 | I19: 0.3 | J19: =G19*I19 -> 1.8 | K19: =J19*TAN(ACOS(H19)) -> 1.35 | L19: =SQRT(J19^2+K19^2) -> 2.25 | M19: Y | N19: 0.3 | O19: =IF(M19="Y",G19*N19,0) -> 1.8 | P19: =O19*TAN(ACOS(H19)) -> 1.35 | Q19: N
A20: 16 | B20: SF | C20: 16A power sockets | D20: F03 | E20: 10 | F20: 1 | G20: =E20*F20 -> 10 | H20: 0.8 | I20: 0.4 | J20: =G20*I20 -> 4 | K20: =J20*TAN(ACOS(H20)) -> 3 | L20: =SQRT(J20^2+K20^2) -> 5 | M20: Y | N20: 0.4 | O20: =IF(M20="Y",G20*N20,0) -> 4 | P20: =O20*TAN(ACOS(H20)) -> 3 | Q20: N
A21: 17 | B21: SF | C21: Toilet exhaust fans | D21: F03 | E21: 4 | F21: 0.1 | G21: =E21*F21 -> 0.4 | H21: 0.8 | I21: 1 | J21: =G21*I21 -> 0.4 | K21: =J21*TAN(ACOS(H21)) -> 0.3 | L21: =SQRT(J21^2+K21^2) -> 0.5 | M21: Y | N21: 1 | O21: =IF(M21="Y",G21*N21,0) -> 0.4 | P21: =O21*TAN(ACOS(H21)) -> 0.3 | Q21: N
A22: 18 | B22: SF | C22: Workstation UPS sockets | D22: F08 | E22: 60 | F22: 0.15 | G22: =E22*F22 -> 9 | H22: 0.9 | I22: 0.8 | J22: =G22*I22 -> 7.2 | K22: =J22*TAN(ACOS(H22)) -> 3.4871192 | L22: =SQRT(J22^2+K22^2) -> 8 | M22: Y | N22: 0.8 | O22: =IF(M22="Y",G22*N22,0) -> 7.2 | P22: =O22*TAN(ACOS(H22)) -> 3.4871192 | Q22: Y | R22: Fed via UPS
A23: 19 | B23: Terrace | C23: VRF outdoor units (~30 TR per floor) | D23: F04 | E23: 9 | F23: 10 | G23: =E23*F23 -> 90 | H23: 0.9 | I23: 0.85 | J23: =G23*I23 -> 76.5 | K23: =J23*TAN(ACOS(H23)) -> 37.050641 | L23: =SQRT(J23^2+K23^2) -> 85 | M23: Y | N23: 0.5 | O23: =IF(M23="Y",G23*N23,0) -> 45 | P23: =O23*TAN(ACOS(H23)) -> 21.794495 | Q23: N | R23: 50% HVAC on DG (load shedding)
A24: 20 | B24: All floors | C24: VRF indoor units / FCU fans | D24: F04 | E24: 30 | F24: 0.1 | G24: =E24*F24 -> 3 | H24: 0.85 | I24: 0.9 | J24: =G24*I24 -> 2.7 | K24: =J24*TAN(ACOS(H24)) -> 1.6733097 | L24: =SQRT(J24^2+K24^2) -> 3.1764706 | M24: Y | N24: 0.9 | O24: =IF(M24="Y",G24*N24,0) -> 2.7 | P24: =O24*TAN(ACOS(H24)) -> 1.6733097 | Q24: N
A25: 21 | B25: Terrace | C25: Fresh-air / ventilation fans | D25: F04 | E25: 3 | F25: 1.5 | G25: =E25*F25 -> 4.5 | H25: 0.85 | I25: 1 | J25: =G25*I25 -> 4.5 | K25: =J25*TAN(ACOS(H25)) -> 2.7888495 | L25: =SQRT(J25^2+K25^2) -> 5.2941176 | M25: Y | N25: 1 | O25: =IF(M25="Y",G25*N25,0) -> 4.5 | P25: =O25*TAN(ACOS(H25)) -> 2.7888495 | Q25: N
A26: 22 | B26: Lift core | C26: Passenger lift, 8-pax, VVVF | D26: F05 | E26: 1 | F26: 11 | G26: =E26*F26 -> 11 | H26: 0.85 | I26: 1 | J26: =G26*I26 -> 11 | K26: =J26*TAN(ACOS(H26)) -> 6.8171877 | L26: =SQRT(J26^2+K26^2) -> 12.941176 | M26: Y | N26: 1 | O26: =IF(M26="Y",G26*N26,0) -> 11 | P26: =O26*TAN(ACOS(H26)) -> 6.8171877 | Q26: N
A27: 23 | B27: Pump room | C27: Domestic transfer pumps (1W + 1S) | D27: F06 | E27: 2 | F27: 3.7 | G27: =E27*F27 -> 7.4 | H27: 0.85 | I27: 0.5 | J27: =G27*I27 -> 3.7 | K27: =J27*TAN(ACOS(H27)) -> 2.2930541 | L27: =SQRT(J27^2+K27^2) -> 4.3529412 | M27: Y | N27: 0.5 | O27: =IF(M27="Y",G27*N27,0) -> 3.7 | P27: =O27*TAN(ACOS(H27)) -> 2.2930541 | Q27: N | R27: Standby not simultaneous
A28: 24 | B28: Pump room | C28: Sewage treatment plant | D28: F06 | E28: 1 | F28: 5.5 | G28: =E28*F28 -> 5.5 | H28: 0.85 | I28: 0.8 | J28: =G28*I28 -> 4.4 | K28: =J28*TAN(ACOS(H28)) -> 2.7268751 | L28: =SQRT(J28^2+K28^2) -> 5.1764706 | M28: Y | N28: 0.8 | O28: =IF(M28="Y",G28*N28,0) -> 4.4 | P28: =O28*TAN(ACOS(H28)) -> 2.7268751 | Q28: N
A29: 25 | B29: Pump room | C29: Main fire pump (electric) | D29: F07 | E29: 1 | F29: 30 | G29: =E29*F29 -> 30 | H29: 0.85 | I29: 0 | J29: =G29*I29 -> 0 | K29: =J29*TAN(ACOS(H29)) -> 0 | L29: =SQRT(J29^2+K29^2) -> 0 | M29: Y | N29: 1 | O29: =IF(M29="Y",G29*N29,0) -> 30 | P29: =O29*TAN(ACOS(H29)) -> 18.59233 | Q29: N | R29: Runs only during fire; HVAC shed then. Full on DG
A30: 26 | B30: Pump room | C30: Jockey pump | D30: F07 | E30: 1 | F30: 3.7 | G30: =E30*F30 -> 3.7 | H30: 0.85 | I30: 0.2 | J30: =G30*I30 -> 0.74 | K30: =J30*TAN(ACOS(H30)) -> 0.45861081 | L30: =SQRT(J30^2+K30^2) -> 0.87058824 | M30: Y | N30: 1 | O30: =IF(M30="Y",G30*N30,0) -> 3.7 | P30: =O30*TAN(ACOS(H30)) -> 2.2930541 | Q30: N | R30: Intermittent
A31: 27 | B31: Parking | C31: EV chargers, AC 7.4 kW | D31: F09 | E31: 2 | F31: 7.4 | G31: =E31*F31 -> 14.8 | H31: 0.99 | I31: 1 | J31: =G31*I31 -> 14.8 | K31: =J31*TAN(ACOS(H31)) -> 2.1088858 | L31: =SQRT(J31^2+K31^2) -> 14.949495 | M31: N | N31: 0 | O31: =IF(M31="Y",G31*N31,0) -> 0 | P31: =O31*TAN(ACOS(H31)) -> 0 | Q31: N | R31: Not on DG
A32: 28 | B32: External | C32: Landscape / street lighting | D32: F10 | E32: 1 | F32: 3 | G32: =E32*F32 -> 3 | H32: 0.9 | I32: 1 | J32: =G32*I32 -> 3 | K32: =J32*TAN(ACOS(H32)) -> 1.4529663 | L32: =SQRT(J32^2+K32^2) -> 3.3333333 | M32: Y | N32: 1 | O32: =IF(M32="Y",G32*N32,0) -> 3 | P32: =O32*TAN(ACOS(H32)) -> 1.4529663 | Q32: N
A33: 29 | B33: External | C33: Signage | D33: F10 | E33: 1 | F33: 1 | G33: =E33*F33 -> 1 | H33: 0.9 | I33: 1 | J33: =G33*I33 -> 1 | K33: =J33*TAN(ACOS(H33)) -> 0.4843221 | L33: =SQRT(J33^2+K33^2) -> 1.1111111 | M33: Y | N33: 1 | O33: =IF(M33="Y",G33*N33,0) -> 1 | P33: =O33*TAN(ACOS(H33)) -> 0.4843221 | Q33: N
C34: TOTAL (before diversity) | G34: =SUM(G5:G33) -> 271.664 | J34: =SUM(J5:J33) -> 180.9226 | K34: =SUM(K5:K33) -> 91.135766 | L34: =SQRT(J34^2+K34^2) -> 202.58014 | O34: =SUM(O5:O33) -> 167.5826 | P34: =SUM(P5:P33) -> 94.197507

Sheet Sizing
B1: Equipment sizing: transformer, DG, UPS, APFC
B3: A. Maximum demand
B4: Item | C4: Value | D4: Unit | E4: Formula / note
B5: Total connected load | C5: =Load_Schedule!G34 -> 271.664 | D5: kW | E5: Load_Schedule total
B6: Sum of feeder MD | C6: =Load_Schedule!J34 -> 180.9226 | D6: kW | E6: Σ (CL x DF)
B7: Sum of feeder MD (reactive) | C7: =Load_Schedule!K34 -> 91.135766 | D7: kVAr
B8: Building MD after diversity | C8: =$C$6*Inputs!$C$8 -> 162.83034 | D8: kW | E8: x overall diversity factor
B9: Building MD after diversity (reactive) | C9: =$C$7*Inputs!$C$8 -> 82.022189 | D9: kVAr
B10: Building MD | C10: =SQRT($C$8^2+$C$9^2) -> 182.32213 | D10: kVA | E10: √(kW² + kVAr²)
B11: Uncorrected power factor | C11: =$C$8/$C$10 -> 0.89309147 | D11: -
B13: B. Distribution transformer (11/0.433 kV, Dyn11, ONAN)
B14: Item | C14: Value | D14: Unit | E14: Formula / note
B15: Required rating | C15: =$C$10*(1+Inputs!$C$9)/Inputs!$C$10 -> 273.4832 | D15: kVA | E15: MD x (1 + margin) / max loading
B16: Selected transformer | C16: =IFERROR(INDEX(Ref_Tables!$M$5:$M$17,COUNTIF(Ref_Tables!$M$5:$M$17,"<"&$C$15)+1),"Exceeds table") -> 315 | D16: kVA | E16: Next IS 1180 standard rating
B17: Loading at present MD | C17: =$C$10/$C$16 -> 0.57880041 | D17: -
B18: LV full-load current | C18: =$C$16*1000/(SQRT(3)*Inputs!$C$7) -> 438.22972 | D18: A | E18: kVA x 1000 / (√3 x V)
B19: HV full-load current | C19: =$C$16/(SQRT(3)*Inputs!$C$6) -> 16.533212 | D19: A
B20: LV fault level (infinite source) | C20: =$C$18/Inputs!$C$11/1000 -> 9.7384383 | D20: kA | E20: I_FL / Z%. Conservative; MLTP rated 25 kA, 1 s
B22: C. Diesel generator (AMF, prime rated)
B23: Item | C23: Value | D23: Unit | E23: Formula / note
B24: Essential demand | C24: =Load_Schedule!O34*Inputs!$C$8 -> 150.82434 | D24: kW | E24: Σ DG demand x diversity
B25: Essential demand (reactive) | C25: =Load_Schedule!P34*Inputs!$C$8 -> 84.777756 | D25: kVAr
B26: Essential demand | C26: =SQRT($C$24^2+$C$25^2) -> 173.01806 | D26: kVA
B27: Required rating | C27: =$C$26*(1+Inputs!$C$9)/Inputs!$C$12 -> 259.52709 | D27: kVA | E27: x (1 + margin) / max loading
B28: Selected DG set | C28: =IFERROR(INDEX(Ref_Tables!$O$5:$O$22,COUNTIF(Ref_Tables!$O$5:$O$22,"<"&$C$27)+1),"Exceeds table") -> 320 | D28: kVA | E28: Next standard rating, 415 V, 0.8 PF
B29: Loading at essential demand | C29: =$C$26/$C$28 -> 0.54068144 | D29: -
B30: Fire pump starting kVA (star-delta) | C30: =30/(0.9*0.85)*6/3 -> 78.431373 | D30: kVA | E30: kW / (η x PF) x LRC 6 / 3 for star-delta. Largest motor step
B31: Starting kVA as % of DG rating | C31: =$C$30/$C$28 -> 0.24509804 | D31: - | E31: Confirm voltage dip with DG maker (ISO 8528-5)
B32: DG full-load current | C32: =$C$28*1000/(SQRT(3)*Inputs!$C$7) -> 445.18575 | D32: A
B34: D. UPS & battery (online, double conversion)
B35: Item | C35: Value | D35: Unit | E35: Formula / note
B36: UPS-backed demand | C36: =SUMIFS(Load_Schedule!$J$5:$J$33,Load_Schedule!$Q$5:$Q$33,"Y") -> 22.4 | D36: kW | E36: Σ MD where UPS backed = Y
B37: UPS-backed demand | C37: =$C$36/Inputs!$C$14 -> 24.888889 | D37: kVA | E37: kW / UPS output PF
B38: Required rating | C38: =$C$37*(1+Inputs!$C$9) -> 29.866667 | D38: kVA | E38: x (1 + margin)
B39: Selected UPS | C39: =IFERROR(INDEX(Ref_Tables!$Q$5:$Q$16,COUNTIF(Ref_Tables!$Q$5:$Q$16,"<"&$C$38)+1),"Exceeds table") -> 30 | D39: kVA | E39: Next standard rating
B40: UPS loading | C40: =$C$37/$C$39 -> 0.82962963 | D40: -
B41: Battery capacity required | C41: =$C$39*Inputs!$C$14*1000*Inputs!$C$16*Inputs!$C$18/(Inputs!$C$17*Inputs!$C$15) -> 47.253024 | D41: Ah | E41: P_rated x t x ageing / (V_dc x η). Check against maker's constant-power tables
B42: Selected battery | C42: =IFERROR(INDEX(Ref_Tables!$S$5:$S$15,COUNTIF(Ref_Tables!$S$5:$S$15,"<"&$C$41)+1),"Exceeds table") -> 65 | D42: Ah | E42: =""&Inputs!$C$17/12&" x 12 V VRLA blocks" -> 32 x 12 V VRLA blocks
B43: UPS input demand | C43: =$C$39*Inputs!$C$14/Inputs!$C$15*(1+Inputs!$C$19)/0.95 -> 33.616299 | D43: kVA | E43: Rated kW / η x (1 + charging), at 0.95 input PF. Used for UPS feeder
B45: E. APFC panel
...

Sheet Cable_Schedule
A1: LT cable schedule: Main LT Panel feeders
A2: Breaker In ≥ Ib; cable Iz (derated) ≥ In; ΔV% = mV/A/m x I x L / (1000 x V) ≤ limit. Size = larger of ampacity and voltage-drop requirement. 0.6/1 kV Al XLPE armoured (Havells), 3.5 core (4 core for 16 mm²), on tray.
A4: Tag | B4: From | C4: To | D4: Load basis | E4: Load (kVA) | F4: Ib (A) | G4: Breaker In (A) | H4: Length (m) | I4: Runs | J4: Temp factor | K4: Group factor | L4: Total derating | M4: Iz needed / run (A) | N4: Idx (ampacity) | O4: Max mV/A/m for ΔV | P4: Idx (ΔV) | Q4: Final idx | R4: Size (mm²) | S4: Cable | T4: Iz derated total (A) | U4: ΔV (%) | V4: Check | W4: Governed by
A5: I01 | B5: Transformer | C5: Main LT Panel | D5: Transformer rating | E5: =Sizing!$C$16 -> 315 | F5: =E5*1000/(SQRT(3)*Inputs!$C$7) -> 438.22972 | G5: =IFERROR(INDEX(Ref_Tables!$K$5:$K$27,COUNTIF(Ref_Tables!$K$5:$K$27,"<"&F5)+1),"Exceeds table") -> 500 | H5: 15 | I5: 2 | J5: =Inputs!$C$21 -> 0.87 | K5: =Inputs!$C$22 -> 0.71 | L5: =J5*K5 -> 0.6177 | M5: =G5/(I5*L5) -> 404.72721 | N5: =COUNTIF(Ref_Tables!$C$5:$C$15,"<"&M5)+1 -> 10 | O5: =Inputs!$C$20*Inputs!$C$7*1000/((F5/I5)*H5) -> 3.7879676 | P5: =COUNTIF(Ref_Tables!$F$5:$F$15,">"&O5)+1 -> 2 | Q5: =MAX(N5,P5) -> 10 | R5: =IF(Q5>11,"Add run",INDEX(Ref_Tables!$B$5:$B$15,Q5)) -> 240 | S5: =IF(Q5>11,"Increase runs",I5&"R x "&IF(R5=16,"4C","3.5C")&" x "&R5&" sq.mm Al XLPE armd") -> 2R x 3.5C x 240 sq.mm Al XLPE armd | T5: =IF(Q5>11,0,INDEX(Ref_Tables!$C$5:$C$15,Q5)*L5*I5) -> 505.2786 | U5: =IF(Q5>11,0,INDEX(Ref_Tables!$F$5:$F$15,Q5)*(F5/I5)*H5/(1000*Inputs!$C$7)) -> 0.0024272287 | V5: =IF(AND(Q5<=11,T5>=G5,U5<=Inputs!$C$20),"OK","CHECK") -> OK | W5: =IF(P5>N5,"Voltage drop","Ampacity") -> Ampacity
A6: I02 | B6: DG set | C6: Main LT Panel (via AMF) | D6: DG rating | E6: =Sizing!$C$28 -> 320 | F6: =E6*1000/(SQRT(3)*Inputs!$C$7) -> 445.18575 | G6: =IFERROR(INDEX(Ref_Tables!$K$5:$K$27,COUNTIF(Ref_Tables!$K$5:$K$27,"<"&F6)+1),"Exceeds table") -> 500 | H6: 25 | I6: 2 | J6: =Inputs!$C$21 -> 0.87 | K6: =Inputs!$C$22 -> 0.71 | L6: =J6*K6 -> 0.6177 | M6: =G6/(I6*L6) -> 404.72721 | N6: =COUNTIF(Ref_Tables!$C$5:$C$15,"<"&M6)+1 -> 10 | O6: =Inputs!$C$20*Inputs!$C$7*1000/((F6/I6)*H6) -> 2.2372684 | P6: =COUNTIF(Ref_Tables!$F$5:$F$15,">"&O6)+1 -> 3 | Q6: =MAX(N6,P6) -> 10 | R6: =IF(Q6>11,"Add run",INDEX(Ref_Tables!$B$5:$B$15,Q6)) -> 240 | S6: =IF(Q6>11,"Increase runs",I6&"R x "&IF(R6=16,"4C","3.5C")&" x "&R6&" sq.mm Al XLPE armd") -> 2R x 3.5C x 240 sq.mm Al XLPE armd | T6: =IF(Q6>11,0,INDEX(Ref_Tables!$C$5:$C$15,Q6)*L6*I6) -> 505.2786 | U6: =IF(Q6>11,0,INDEX(Ref_Tables!$F$5:$F$15,Q6)*(F6/I6)*H6/(1000*Inputs!$C$7)) -> 0.0041095936 | V6: =IF(AND(Q6<=11,T6>=G6,U6<=Inputs!$C$20),"OK","CHECK") -> OK | W6: =IF(P6>N6,"Voltage drop","Ampacity") -> Ampacity
A7: F01 | B7: Main LT Panel | C7: GF Floor DB | D7: Load_Schedule MD | E7: =SUMIFS(Load_Schedule!$L$5:$L$33,Load_Schedule!$D$5:$D$33,"F01") -> 21.351176 | F7: =E7*1000/(SQRT(3)*Inputs!$C$7) -> 29.703873 | G7: =IFERROR(INDEX(Ref_Tables!$K$5:$K$27,COUNTIF(Ref_Tables!$K$5:$K$27,"<"&F7)+1),"Exceeds table") -> 32 | H7: 20 | I7: 1 | J7: =Inputs!$C$21 -> 0.87 | K7: =Inputs!$C$22 -> 0.71 | L7: =J7*K7 -> 0.6177 | M7: =G7/(I7*L7) -> 51.805083 | N7: =COUNTIF(Ref_Tables!$C$5:$C$15,"<"&M7)+1 -> 1 | O7: =Inputs!$C$20*Inputs!$C$7*1000/((F7/I7)*H7) -> 20.956863 | P7: =COUNTIF(Ref_Tables!$F$5:$F$15,">"&O7)+1 -> 1 | Q7: =MAX(N7,P7) -> 1 | R7: =IF(Q7>11,"Add run",INDEX(Ref_Tables!$B$5:$B$15,Q7)) -> 16 | S7: =IF(Q7>11,"Increase runs",I7&"R x "&IF(R7=16,"4C","3.5C")&" x "&R7&" sq.mm Al XLPE armd") -> 1R x 4C x 16 sq.mm Al XLPE armd | T7: =IF(Q7>11,0,INDEX(Ref_Tables!$C$5:$C$15,Q7)*L7*I7) -> 47.5629 | U7: =IF(Q7>11,0,INDEX(Ref_Tables!$F$5:$F$15,Q7)*(F7/I7)*H7/(1000*Inputs!$C$7)) -> 0.0060751946 | V7: =IF(AND(Q7<=11,T7>=G7,U7<=Inputs!$C$20),"OK","CHECK") -> OK | W7: =IF(P7>N7,"Voltage drop","Ampacity") -> Ampacity
A8: F02 | B8: Main LT Panel | C8: FF Floor DB | D8: Load_Schedule MD | E8: =SUMIFS(Load_Schedule!$L$5:$L$33,Load_Schedule!$D$5:$D$33,"F02") -> 10.702 | F8: =E8*1000/(SQRT(3)*Inputs!$C$7) -> 14.888681 | G8: =IFERROR(INDEX(Ref_Tables!$K$5:$K$27,COUNTIF(Ref_Tables!$K$5:$K$27,"<"&F8)+1),"Exceeds table") -> 16 | H8: 30 | I8: 1 | J8: =Inputs!$C$21 -> 0.87 | K8: =Inputs!$C$22 -> 0.71 | L8: =J8*K8 -> 0.6177 | M8: =G8/(I8*L8) -> 25.902542 | N8: =COUNTIF(Ref_Tables!$C$5:$C$15,"<"&M8)+1 -> 1 | O8: =Inputs!$C$20*Inputs!$C$7*1000/((F8/I8)*H8) -> 27.873524 | P8: =COUNTIF(Ref_Tables!$F$5:$F$15,">"&O8)+1 -> 1 | Q8: =MAX(N8,P8) -> 1 | R8: =IF(Q8>11,"Add run",INDEX(Ref_Tables!$B$5:$B$15,Q8)) -> 16 | S8: =IF(Q8>11,"Increase runs",I8&"R x "&IF(R8=16,"4C","3.5C")&" x "&R8&" sq.mm Al XLPE armd") -> 1R x 4C x 16 sq.mm Al XLPE armd | T8: =IF(Q8>11,0,INDEX(Ref_Tables!$C$5:$C$15,Q8)*L8*I8) -> 47.5629 | U8: =IF(Q8>11,0,INDEX(Ref_Tables!$F$5:$F$15,Q8)*(F8/I8)*H8/(1000*Inputs!$C$7)) -> 0.0045676687 | V8: =IF(AND(Q8<=11,T8>=G8,U8<=Inputs!$C$20),"OK","CHECK") -> OK | W8: =IF(P8>N8,"Voltage drop","Ampacity") -> Ampacity
A9: F03 | B9: Main LT Panel | C9: SF Floor DB | D9: Load_Schedule MD | E9: =SUMIFS(Load_Schedule!$L$5:$L$33,Load_Schedule!$D$5:$D$33,"F03") -> 10.702 | F9: =E9*1000/(SQRT(3)*Inputs!$C$7) -> 14.888681 | G9: =IFERROR(INDEX(Ref_Tables!$K$5:$K$27,COUNTIF(Ref_Tables!$K$5:$K$27,"<"&F9)+1),"Exceeds table") -> 16 | H9: 40 | I9: 1 | J9: =Inputs!$C$21 -> 0.87 | K9: =Inputs!$C$22 -> 0.71 | L9: =J9*K9 -> 0.6177 | M9: =G9/(I9*L9) -> 25.902542 | N9: =COUNTIF(Ref_Tables!$C$5:$C$15,"<"&M9)+1 -> 1 | O9: =Inputs!$C$20*Inputs!$C$7*1000/((F9/I9)*H9) -> 20.905143 | P9: =COUNTIF(Ref_Tables!$F$5:$F$15,">"&O9)+1 -> 1 | Q9: =MAX(N9,P9) -> 1 | R9: =IF(Q9>11,"Add run",INDEX(Ref_Tables!$B$5:$B$15,Q9)) -> 16 | S9: =IF(Q9>11,"Increase runs",I9&"R x "&IF(R9=16,"4C","3.5C")&" x "&R9&" sq.mm Al XLPE armd") -> 1R x 4C x 16 sq.mm Al XLPE armd | T9: =IF(Q9>11,0,INDEX(Ref_Tables!$C$5:$C$15,Q9)*L9*I9) -> 47.5629 | U9: =IF(Q9>11,0,INDEX(Ref_Tables!$F$5:$F$15,Q9)*(F9/I9)*H9/(1000*Inputs!$C$7)) -> 0.0060902249 | V9: =IF(AND(Q9<=11,T9>=G9,U9<=Inputs!$C$20),"OK","CHECK") -> OK | W9: =IF(P9>N9,"Voltage drop","Ampacity") -> Ampacity
A10: F04 | B10: Main LT Panel | C10: HVAC Panel (terrace) | D10: Load_Schedule MD | E10: =SUMIFS(Load_Schedule!$L$5:$L$33,Load_Schedule!$D$5:$D$33,"F04") -> 93.470588 | F10: =E10*1000/(SQRT(3)*Inputs!$C$7) -> 130.03679 | G10: =IFERROR(INDEX(Ref_Tables!$K$5:$K$27,COUNTIF(Ref_Tables!$K$5:$K$27,"<"&F10)+1),"Exceeds table") -> 160 | H10: 45 | I10: 1 | J10: =Inputs!$C$21 -> 0.87 | K10: =Inputs!$C$22 -> 0.71 | L10: =J10*K10 -> 0.6177 | M10: =G10/(I10*L10) -> 259.02542 | N10: =COUNTIF(Ref_Tables!$C$5:$C$15,"<"&M10)+1 -> 7 | O10: =Inputs!$C$20*Inputs!$C$7*1000/((F10/I10)*H10) -> 2.127603 | P10: =COUNTIF(Ref_Tables!$F$5:$F$15,">"&O10)+1 -> 3 | Q10: =MAX(N10,P10) -> 7 | R10: =IF(Q10>11,"Add run",INDEX(Ref_Tables!$B$5:$B$15,Q10)) -> 120 | S10: =IF(Q10>11,"Increase runs",I10&"R x "&IF(R10=16,"4C","3.5C")&" x "&R10&" sq.mm Al XLPE armd") -> 1R x 3.5C x 120 sq.mm Al XLPE armd | T10: =IF(Q10>11,0,INDEX(Ref_Tables!$C$5:$C$15,Q10)*L10*I10) -> 162.4551 | U10: =IF(Q10>11,0,INDEX(Ref_Tables!$F$5:$F$15,Q10)*(F10/I10)*H10/(1000*Inputs!$C$7)) -> 0.0081365179 | V10: =IF(AND(Q10<=11,T10>=G10,U10<=Inputs!$C$20),"OK","CHECK") -> OK | W10: =IF(P10>N10,"Voltage drop","Ampacity") -> Ampacity
A11: F05 | B11: Main LT Panel | C11: Lift Panel | D11: Load_Schedule MD | E11: =SUMIFS(Load_Schedule!$L$5:$L$33,Load_Schedule!$D$5:$D$33,"F05") -> 12.941176 | F11: =E11*1000/(SQRT(3)*Inputs!$C$7) -> 18.003835 | G11: =IFERROR(INDEX(Ref_Tables!$K$5:$K$27,COUNTIF(Ref_Tables!$K$5:$K$27,"<"&F11)+1),"Exceeds table") -> 20 | H11: 50 | I11: 1 | J11: =Inputs!$C$21 -> 0.87 | K11: =Inputs!$C$22 -> 0.71 | L11: =J11*K11 -> 0.6177 | M11: =G11/(I11*L11) -> 32.378177 | N11: =COUNTIF(Ref_Tables!$C$5:$C$15,"<"&M11)+1 -> 1 | O11: =Inputs!$C$20*Inputs!$C$7*1000/((F11/I11)*H11) -> 13.830386 | P11: =COUNTIF(Ref_Tables!$F$5:$F$15,">"&O11)+1 -> 1 | Q11: =MAX(N11,P11) -> 1 | R11: =IF(Q11>11,"Add run",INDEX(Ref_Tables!$B$5:$B$15,Q11)) -> 16 | S11: =IF(Q11>11,"Increase runs",I11&"R x "&IF(R11=16,"4C","3.5C")&" x "&R11&" sq.mm Al XLPE armd") -> 1R x 4C x 16 sq.mm Al XLPE armd | T11: =IF(Q11>11,0,INDEX(Ref_Tables!$C$5:$C$15,Q11)*L11*I11) -> 47.5629 | U11: =IF(Q11>11,0,INDEX(Ref_Tables!$F$5:$F$15,Q11)*(F11/I11)*H11/(1000*Inputs!$C$7)) -> 0.0092056011 | V11: =IF(AND(Q11<=11,T11>=G11,U11<=Inputs!$C$20),"OK","CHECK") -> OK | W11: =IF(P11>N11,"Voltage drop","Ampacity") -> Ampacity
A12: F06 | B12: Main LT Panel | C12: Pump & STP Panel | D12: Load_Schedule MD | E12: =SUMIFS(Load_Schedule!$L$5:$L$33,Load_Schedule!$D$5:$D$33,"F06") -> 9.5294118 | F12: =E12*1000/(SQRT(3)*Inputs!$C$7) -> 13.25737 | G12: =IFERROR(INDEX(Ref_Tables!$K$5:$K$27,COUNTIF(Ref_Tables!$K$5:$K$27,"<"&F12)+1),"Exceeds table") -> 16 | H12: 30 | I12: 1 | J12: =Inputs!$C$21 -> 0.87 | K12: =Inputs!$C$22 -> 0.71 | L12: =J12*K12 -> 0.6177 | M12: =G12/(I12*L12) -> 25.902542 | N12: =COUNTIF(Ref_Tables!$C$5:$C$15,"<"&M12)+1 -> 1 | O12: =Inputs!$C$20*Inputs!$C$7*1000/((F12/I12)*H12) -> 31.303344 | P12: =COUNTIF(Ref_Tables!$F$5:$F$15,">"&O12)+1 -> 1 | Q12: =MAX(N12,P12) -> 1 | R12: =IF(Q12>11,"Add run",INDEX(Ref_Tables!$B$5:$B$15,Q12)) -> 16 | S12: =IF(Q12>11,"Increase runs",I12&"R x "&IF(R12=16,"4C","3.5C")&" x "&R12&" sq.mm Al XLPE armd") -> 1R x 4C x 16 sq.mm Al XLPE armd | T12: =IF(Q12>11,0,INDEX(Ref_Tables!$C$5:$C$15,Q12)*L12*I12) -> 47.5629 | U12: =IF(Q12>11,0,INDEX(Ref_Tables!$F$5:$F$15,Q12)*(F12/I12)*H12/(1000*Inputs!$C$7)) -> 0.004067202 | V12: =IF(AND(Q12<=11,T12>=G12,U12<=Inputs!$C$20),"OK","CHECK") -> OK | W12: =IF(P12>N12,"Voltage drop","Ampacity") -> Ampacity
A13: F07 | B13: Main LT Panel | C13: Fire Pump Panel | D13: Full load (fire pump + jockey) | E13: =SUMIFS(Load_Schedule!$G$5:$G$33,Load_Schedule!$D$5:$D$33,"F07")/0.85 -> 39.647059 | F13: =E13*1000/(SQRT(3)*Inputs!$C$7) -> 55.157205 | G13: =IFERROR(INDEX(Ref_Tables!$K$5:$K$27,COUNTIF(Ref_Tables!$K$5:$K$27,"<"&F13)+1),"Exceeds table") -> 63 | H13: 25 | I13: 1 | J13: =Inputs!$C$21 -> 0.87 | K13: =Inputs!$C$22 -> 0.71 | L13: =J13*K13 -> 0.6177 | M13: =G13/(I13*L13) -> 101.99126 | N13: =COUNTIF(Ref_Tables!$C$5:$C$15,"<"&M13)+1 -> 3 | O13: =Inputs!$C$20*Inputs!$C$7*1000/((F13/I13)*H13) -> 9.0287389 | P13: =COUNTIF(Ref_Tables!$F$5:$F$15,">"&O13)+1 -> 1 | Q13: =MAX(N13,P13) -> 3 | R13: =IF(Q13>11,"Add run",INDEX(Ref_Tables!$B$5:$B$15,Q13)) -> 35 | S13: =IF(Q13>11,"Increase runs",I13&"R x "&IF(R13=16,"4C","3.5C")&" x "&R13&" sq.mm Al XLPE armd") -> 1R x 3.5C x 35 sq.mm Al XLPE armd | T13: =IF(Q13>11,0,INDEX(Ref_Tables!$C$5:$C$15,Q13)*L13*I13) -> 74.124 | U13: =IF(Q13>11,0,INDEX(Ref_Tables!$F$5:$F$15,Q13)*(F13/I13)*H13/(1000*Inputs!$C$7)) -> 0.0064211923 | V13: =IF(AND(Q13<=11,T13>=G13,U13<=Inputs!$C$20),"OK","CHECK") -> OK | W13: =IF(P13>N13,"Voltage drop","Ampacity") -> Ampacity
A14: F08 | B14: Main LT Panel | C14: UPS input | D14: UPS input demand | E14: =Sizing!$C$43 -> 33.616299 | F14: =E14*1000/(SQRT(3)*Inputs!$C$7) -> 46.767179 | G14: =IFERROR(INDEX(Ref_Tables!$K$5:$K$27,COUNTIF(Ref_Tables!$K$5:$K$27,"<"&F14)+1),"Exceeds table") -> 50 | H14: 15 | I14: 1 | J14: =Inputs!$C$21 -> 0.87 | K14: =Inputs!$C$22 -> 0.71 | L14: =J14*K14 -> 0.6177 | M14: =G14/(I14*L14) -> 80.945443 | N14: =COUNTIF(Ref_Tables!$C$5:$C$15,"<"&M14)+1 -> 2 | O14: =Inputs!$C$20*Inputs!$C$7*1000/((F14/I14)*H14) -> 17.747489 | P14: =COUNTIF(Ref_Tables!$F$5:$F$15,">"&O14)+1 -> 1 | Q14: =MAX(N14,P14) -> 2 | R14: =IF(Q14>11,"Add run",INDEX(Ref_Tables!$B$5:$B$15,Q14)) -> 25 | S14: =IF(Q14>11,"Increase runs",I14&"R x "&IF(R14=16,"4C","3.5C")&" x "&R14&" sq.mm Al XLPE armd") -> 1R x 3.5C x 25 sq.mm Al XLPE armd | T14: =IF(Q14>11,0,INDEX(Ref_Tables!$C$5:$C$15,Q14)*L14*I14) -> 59.9169 | U14: =IF(Q14>11,0,INDEX(Ref_Tables!$F$5:$F$15,Q14)*(F14/I14)*H14/(1000*Inputs!$C$7)) -> 0.0045109091 | V14: =IF(AND(Q14<=11,T14>=G14,U14<=Inputs!$C$20),"OK","CHECK") -> OK | W14: =IF(P14>N14,"Voltage drop","Ampacity") -> Ampacity
A15: F09 | B15: Main LT Panel | C15: EV Charger DB | D15: Load_Schedule MD | E15: =SUMIFS(Load_Schedule!$L$5:$L$33,Load_Schedule!$D$5:$D$33,"F09") -> 14.949495 | F15: =E15*1000/(SQRT(3)*Inputs!$C$7) -> 20.797819 | G15: =IFERROR(INDEX(Ref_Tables!$K$5:$K$27,COUNTIF(Ref_Tables!$K$5:$K$27,"<"&F15)+1),"Exceeds table") -> 25 | H15: 40 | I15: 1 | J15: =Inputs!$C$21 -> 0.87 | K15: =Inputs!$C$22 -> 0.71 | L15: =J15*K15 -> 0.6177 | M15: =G15/(I15*L15) -> 40.472721 | N15: =COUNTIF(Ref_Tables!$C$5:$C$15,"<"&M15)+1 -> 1 | O15: =Inputs!$C$20*Inputs!$C$7*1000/((F15/I15)*H15) -> 14.965511 | P15: =COUNTIF(Ref_Tables!$F$5:$F$15,">"&O15)+1 -> 1 | Q15: =MAX(N15,P15) -> 1 | R15: =IF(Q15>11,"Add run",INDEX(Ref_Tables!$B$5:$B$15,Q15)) -> 16 | S15: =IF(Q15>11,"Increase runs",I15&"R x "&IF(R15=16,"4C","3.5C")&" x "&R15&" sq.mm Al XLPE armd") -> 1R x 4C x 16 sq.mm Al XLPE armd | T15: =IF(Q15>11,0,INDEX(Ref_Tables!$C$5:$C$15,Q15)*L15*I15) -> 47.5629 | U15: =IF(Q15>11,0,INDEX(Ref_Tables!$F$5:$F$15,Q15)*(F15/I15)*H15/(1000*Inputs!$C$7)) -> 0.0085073618 | V15: =IF(AND(Q15<=11,T15>=G15,U15<=Inputs!$C$20),"OK","CHECK") -> OK | W15: =IF(P15>N15,"Voltage drop","Ampacity") -> Ampacity
A16: F10 | B16: Main LT Panel | C16: External Lighting DB | D16: Load_Schedule MD | E16: =SUMIFS(Load_Schedule!$L$5:$L$33,Load_Schedule!$D$5:$D$33,"F10") -> 4.4444444 | F16: =E16*1000/(SQRT(3)*Inputs!$C$7) -> 6.1831354 | G16: =IFERROR(INDEX(Ref_Tables!$K$5:$K$27,COUNTIF(Ref_Tables!$K$5:$K$27,"<"&F16)+1),"Exceeds table") -> 16 | H16: 60 | I16: 1 | J16: =Inputs!$C$21 -> 0.87 | K16: =Inputs!$C$22 -> 0.71 | L16: =J16*K16 -> 0.6177 | M16: =G16/(I16*L16) -> 25.902542 | N16: =COUNTIF(Ref_Tables!$C$5:$C$15,"<"&M16)+1 -> 1 | O16: =Inputs!$C$20*Inputs!$C$7*1000/((F16/I16)*H16) -> 33.559026 | P16: =COUNTIF(Ref_Tables!$F$5:$F$15,">"&O16)+1 -> 1 | Q16: =MAX(N16,P16) -> 1 | R16: =IF(Q16>11,"Add run",INDEX(Ref_Tables!$B$5:$B$15,Q16)) -> 16 | S16: =IF(Q16>11,"Increase runs",I16&"R x "&IF(R16=16,"4C","3.5C")&" x "&R16&" sq.mm Al XLPE armd") -> 1R x 4C x 16 sq.mm Al XLPE armd | T16: =IF(Q16>11,0,INDEX(Ref_Tables!$C$5:$C$15,Q16)*L16*I16) -> 47.5629 | U16: =IF(Q16>11,0,INDEX(Ref_Tables!$F$5:$F$15,Q16)*(F16/I16)*H16/(1000*Inputs!$C$7)) -> 0.0037938235 | V16: =IF(AND(Q16<=11,T16>=G16,U16<=Inputs!$C$20),"OK","CHECK") -> OK | W16: =IF(P16>N16,"Voltage drop","Ampacity") -> Ampacity
A17: F11 | B17: Main LT Panel | C17: APFC Panel | D17: 1.43 x capacitor kVA (IEC 60831) | E17: =Sizing!$C$48*1.43 -> 107.25 | F17: =E17*1000/(SQRT(3)*Inputs!$C$7) -> 149.20679 | G17: =IFERROR(INDEX(Ref_Tables!$K$5:$K$27,COUNTIF(Ref_Tables!$K$5:$K$27,"<"&F17)+1),"Exceeds table") -> 160 | H17: 10 | I17: 1 | J17: =Inputs!$C$21 -> 0.87 | K17: =Inputs!$C$22 -> 0.71 | L17: =J17*K17 -> 0.6177 | M17: =G17/(I17*L17) -> 259.02542 | N17: =COUNTIF(Ref_Tables!$C$5:$C$15,"<"&M17)+1 -> 7 | O17: =Inputs!$C$20*Inputs!$C$7*1000/((F17/I17)*H17) -> 8.3441245 | P17: =COUNTIF(Ref_Tables!$F$5:$F$15,">"&O17)+1 -> 1 | Q17: =MAX(N17,P17) -> 7 | R17: =IF(Q17>11,"Add run",INDEX(Ref_Tables!$B$5:$B$15,Q17)) -> 120 | S17: =IF(Q17>11,"Increase runs",I17&"R x "&IF(R17=16,"4C","3.5C")&" x "&R17&" sq.mm Al XLPE armd") -> 1R x 3.5C x 120 sq.mm Al XLPE armd | T17: =IF(Q17>11,0,INDEX(Ref_Tables!$C$5:$C$15,Q17)*L17*I17) -> 162.4551 | U17: =IF(Q17>11,0,INDEX(Ref_Tables!$F$5:$F$15,Q17)*(F17/I17)*H17/(1000*Inputs!$C$7)) -> 0.002074667 | V17: =IF(AND(Q17<=11,T17>=G17,U17<=Inputs!$C$20),"OK","CHECK") -> OK | W17: =IF(P17>N17,"Voltage drop","Ampacity") -> Ampacity
A19: Fire-pump feeder sized on full load (not demand) and must be routed separately as a fire-survival circuit (NBC 2016 Part 4). Short-circuit withstand S ≥ I·√t / k (k = 94, Al XLPE) to be checked against breaker let-through energy.

Sheet Earthing
B1: Earthing design per IS 3043:2018
B3: A. Single pipe electrode
B4: Item | C4: Value | D4: Unit | E4: Formula
B5: Resistance of one electrode, R1 | C5: =Inputs!$C$23/(2*PI()*Inputs!$C$24)*LN(4*Inputs!$C$24/Inputs!$C$25) -> 12.699216 | D5: Ω | E5: R = ρ / (2πL) x ln(4L / d)
B6: Mutual factor α | C6: =Inputs!$C$23/(2*PI()*C5*Inputs!$C$26) -> 0.10443882 | D6: - | E6: α = ρ / (2π R1 s)
B8: B. Interconnecting strip electrode
B9: Item | C9: Value | D9: Unit | E9: Formula
B10: Resistance of buried strip, Rs | C10: =Inputs!$C$23/(2*PI()*Inputs!$C$28)*LN(2*Inputs!$C$28^2/(Inputs!$C$29*Inputs!$C$30)) -> 1.667243 | D10: Ω | E10: R = ρ / (2πL) x ln(2L² / (w t))
B12: C. Number of electrodes (in line) + strip in parallel
G13: n | H13: λ | I13: Rn (Ω) | J13: Grid R (Ω) | K13: Meets target?
B14: Electrodes required in main grid | C14: =IFERROR(INDEX(G14:G23,MATCH("Yes",K14:K23,0)),"> 10: improve soil / longer rods") -> 7 | D14: nos | E14: Smallest n with grid R ≤ target. Rn = R1(1 + λα)/n; grid = Rn ∥ Rs (mutual coupling ignored, so measure after installation) | G14: =Ref_Tables!U5 -> 1 | H14: =Ref_Tables!V5 -> 0 | I14: =$C$5*(1+H14*$C$6)/G14 -> 12.699216 | J14: =1/(1/I14+1/$C$10) -> 1.4737576 | K14: =IF(J14<=Inputs!$C$27,"Yes","No") -> No
B15: Grid resistance achieved | C15: =IFERROR(INDEX(J14:J23,MATCH("Yes",K14:K23,0)),J23) -> 0.98565144 | D15: Ω | G15: =Ref_Tables!U6 -> 2 | H15: =Ref_Tables!V6 -> 1 | I15: =$C$5*(1+H15*$C$6)/G15 -> 7.0127537 | J15: =1/(1/I15+1/$C$10) -> 1.347001 | K15: =IF(J15<=Inputs!$C$27,"Yes","No") -> No
G16: =Ref_Tables!U7 -> 3 | H16: =Ref_Tables!V7 -> 1.66 | I16: =$C$5*(1+H16*$C$6)/G16 -> 4.9669532 | J16: =1/(1/I16+1/$C$10) -> 1.2482473 | K16: =IF(J16<=Inputs!$C$27,"Yes","No") -> No
G17: =Ref_Tables!U8 -> 4 | H17: =Ref_Tables!V8 -> 2.15 | I17: =$C$5*(1+H17*$C$6)/G17 -> 3.8876856 | J17: =1/(1/I17+1/$C$10) -> 1.1668406 | K17: =IF(J17<=Inputs!$C$27,"Yes","No") -> No
G18: =Ref_Tables!U9 -> 5 | H18: =Ref_Tables!V9 -> 2.54 | I18: =$C$5*(1+H18*$C$6)/G18 -> 3.2135992 | J18: =1/(1/I18+1/$C$10) -> 1.0977308 | K18: =IF(J18<=Inputs!$C$27,"Yes","No") -> No
G19: =Ref_Tables!U10 -> 6 | H19: =Ref_Tables!V10 -> 2.87 | I19: =$C$5*(1+H19*$C$6)/G19 -> 2.7509453 | J19: =1/(1/I19+1/$C$10) -> 1.0380939 | K19: =IF(J19<=Inputs!$C$27,"Yes","No") -> No
G20: =Ref_Tables!U11 -> 7 | H20: =Ref_Tables!V11 -> 3.15 | I20: =$C$5*(1+H20*$C$6)/G20 -> 2.4110048 | J20: =1/(1/I20+1/$C$10) -> 0.98565144 | K20: =IF(J20<=Inputs!$C$27,"Yes","No") -> Yes
G21: =Ref_Tables!U12 -> 8 | H21: =Ref_Tables!V12 -> 3.39 | I21: =$C$5*(1+H21*$C$6)/G21 -> 2.1494179 | J21: =1/(1/I21+1/$C$10) -> 0.93893642 | K21: =IF(J21<=Inputs!$C$27,"Yes","No") -> Yes
G22: =Ref_Tables!U13 -> 9 | H22: =Ref_Tables!V13 -> 3.61 | I22: =$C$5*(1+H22*$C$6)/G22 -> 1.9430142 | J22: =1/(1/I22+1/$C$10) -> 0.89729805 | K22: =IF(J22<=Inputs!$C$27,"Yes","No") -> Yes
G23: =Ref_Tables!U14 -> 10 | H23: =Ref_Tables!V14 -> 3.81 | I23: =$C$5*(1+H23*$C$6)/G23 -> 1.7752386 | J23: =1/(1/I23+1/$C$10) -> 0.85977339 | K23: =IF(J23<=Inputs!$C$27,"Yes","No") -> Yes
B25: D. Earthing conductor sizing (adiabatic)
B26: Item | C26: Value | D26: Unit | E26: Formula
B27: Prospective earth fault current | C27: =Sizing!$C$20*1000 -> 9738.4383 | D27: A | E27: Taken = LV 3-ph fault level (conservative)
B28: Minimum area, S | C28: =C27*SQRT(Inputs!$C$31)/Inputs!$C$32 -> 121.73048 | D28: mm² | E28: S = I √t / k
B29: With corrosion allowance | C29: =C28*Inputs!$C$33 -> 182.59572 | D29: mm²
B30: Selected GI strip (main earth conductor) | C30: =IFERROR(INDEX(Ref_Tables!$X$5:$X$11,COUNTIF(Ref_Tables!$Y$5:$Y$11,"<"&C29)+1),"Use copper") -> 32 x 6 | D30: mm
B32: E. Dedicated earth pits (in addition to main grid)
B33: Purpose | C33: Nos | E33: Note
B34: Transformer neutral | C34: 2 | E34: Bonded to grid at one point (TN-S)
B35: DG neutral | C35: 2
B36: UPS / IT clean earth | C36: 2 | E36: Isolated electronic earth, ≤ 0.5 Ω
B37: Lightning protection | C37: 2 | E37: IS/IEC 62305 down-conductor pits

Sheet Ref_Tables
B2: Reference tables
B3: Source: Havells International Cables catalogue, 0.6/1 kV Al XLPE armoured, Tables 16 (3.5C, 25-300) & 20 (4C, 16). Ampacity in air at 30°C. | H3: UF (refl. 70/50/20) | U3: IS 3043 parallel-electrode factor
B4: Size (mm²) | C4: Ampacity in air 30°C (A) | D4: Max R @20°C (Ω/km) | E4: X (Ω/km) | F4: mV/A/m (3-ph, R @90°C) | G4: SC rating 1 s (kA) | H4: Room index K | I4: UF | K4: Breaker In (A) | M4: Transformer (kVA) | O4: DG set (kVA) | Q4: UPS (kVA) | S4: Battery (Ah) | U4: n | V4: λ (in line) | X4: GI strip | Y4: Area (mm²)
B5: 16 | C5: 77 | D5: 1.91 | E5: 0.083 | F5: =SQRT(3)*SQRT((D5*(1+0.00403*70))^2+E5^2) -> 4.2439007 | G5: 1.5 | H5: 0.6 | I5: 0.45 | K5: 16 | M5: 100 | O5: 15 | Q5: 6 | S5: 7 | U5: 1 | V5: 0 | X5: 25 x 3 | Y5: 75
B6: 25 | C6: 97 | D6: 1.2 | E6: 0.082 | F6: =SQRT(3)*SQRT((D6*(1+0.00403*70))^2+E6^2) -> 2.668577 | G6: 2.35 | H6: 0.8 | I6: 0.53 | K6: 20 | M6: 160 | O6: 20 | Q6: 10 | S6: 9 | U6: 2 | V6: 1 | X6: 25 x 6 | Y6: 150
B7: 35 | C7: 120 | D7: 0.868 | E7: 0.08 | F7: =SQRT(3)*SQRT((D7*(1+0.00403*70))^2+E7^2) -> 1.9325089 | G7: 3.29 | H7: 1 | I7: 0.58 | K7: 25 | M7: 200 | O7: 25 | Q7: 15 | S7: 12 | U7: 3 | V7: 1.66 | X7: 32 x 6 | Y7: 192
B8: 50 | C8: 146 | D8: 0.641 | E8: 0.079 | F8: =SQRT(3)*SQRT((D8*(1+0.00403*70))^2+E8^2) -> 1.4300061 | G8: 4.7 | H8: 1.25 | I8: 0.63 | K8: 32 | M8: 250 | O8: 30 | Q8: 20 | S8: 18 | U8: 4 | V8: 2.15 | X8: 40 x 6 | Y8: 240
B9: 70 | C9: 187 | D9: 0.443 | E9: 0.077 | F9: =SQRT(3)*SQRT((D9*(1+0.00403*70))^2+E9^2) -> 0.99275263 | G9: 6.58 | H9: 1.5 | I9: 0.67 | K9: 40 | M9: 315 | O9: 40 | Q9: 30 | S9: 26 | U9: 5 | V9: 2.54 | X9: 50 x 6 | Y9: 300
B10: 95 | C10: 227 | D10: 0.32 | E10: 0.077 | F10: =SQRT(3)*SQRT((D10*(1+0.00403*70))^2+E10^2) -> 0.72301891 | G10: 8.93 | H10: 2 | I10: 0.72 | K10: 50 | M10: 400 | O10: 62.5 | Q10: 40 | S10: 42 | U10: 6 | V10: 2.87 | X10: 50 x 10 | Y10: 500
B11: 120 | C11: 263 | D11: 0.253 | E11: 0.076 | F11: =SQRT(3)*SQRT((D11*(1+0.00403*70))^2+E11^2) -> 0.57704265 | G11: 11.28 | H11: 2.5 | I11: 0.75 | K11: 63 | M11: 500 | O11: 82.5 | Q11: 60 | S11: 65 | U11: 7 | V11: 3.15 | X11: 75 x 10 | Y11: 750
B12: 150 | C12: 304 | D12: 0.206 | E12: 0.076 | F12: =SQRT(3)*SQRT((D12*(1+0.00403*70))^2+E12^2) -> 0.47601932 | G12: 14.1 | H12: 3 | I12: 0.78 | K12: 80 | M12: 630 | O12: 100 | Q12: 80 | S12: 100 | U12: 8 | V12: 3.39
B13: 185 | C13: 347 | D13: 0.164 | E13: 0.076 | F13: =SQRT(3)*SQRT((D13*(1+0.00403*70))^2+E13^2) -> 0.38724844 | G13: 17.39 | H13: 4 | I13: 0.81 | K13: 100 | M13: 800 | O13: 125 | Q13: 100 | S13: 120 | U13: 9 | V13: 3.61
B14: 240 | C14: 409 | D14: 0.125 | E14: 0.075 | F14: =SQRT(3)*SQRT((D14*(1+0.00403*70))^2+E14^2) -> 0.30647546 | G14: 22.56 | H14: 5 | I14: 0.83 | K14: 125 | M14: 1000 | O14: 160 | Q14: 120 | S14: 150 | U14: 10 | V14: 3.81
B15: 300 | C15: 471 | D15: 0.1 | E15: 0.075 | F15: =SQRT(3)*SQRT((D15*(1+0.00403*70))^2+E15^2) -> 0.25727109 | G15: 28.2 | K15: 160 | M15: 1250 | O15: 200 | Q15: 160 | S15: 200
B16: R from catalogue (20°C DC) corrected to 90°C with α(Al) = 0.00403/°C. Catalogue gives no reactance, so X is a typical value for multicore XLPE. 16 mm² taken from the 4-core table (smallest 3.5C size is 25 mm²). | K16: 200 | M16: 1600 | O16: 250 | Q16: 200
K17: 250 | M17: 2000 | O17: 320
K18: 320 | O18: 380
K19: 400 | O19: 500
K20: 500 | O20: 625
K21: 630 | O21: 750
K22: 800 | O22: 1010
K23: 1000
K24: 1250
K25: 1600
K26: 2000
K27: 2500
